## 1.7 异常规格说明

> C++允许在函数后提供修饰符来说明异常情况。

#### 1. 异常修饰符

##### 1.1 可能抛出异常

```C++
void f() throw(toobig, toosmall, divzere);
```

##### 1.2 不抛出任何异常

```C++
void f() throw();
```

##### 1.3 抛出任意类型的异常

```C++
void f();
```

#### 2. 违背异常修饰符

> 如果函数抛出的异常违背了该函数的异常修饰符，则会调用函数`unexpected()`。

##### 2.1 unexpected()函数

> 默认的unexpected()函数会调用terminate()函数，而默认的terminate函数会调用abort()函数。

##### 2.2 set_unexpected()函数

* 参数：函数指针void (*)()
* 返回值：原有函数指针

##### 2.3 演示unexpected函数的替换和隐式调用

```C++
#include <exception>
#include <iostream>
using namespace std;

class Up
{
};
class Fit
{
};
void g();

void f(int i) throw(Up, Fit)
{
    switch (i)
    {
    case 1:
        throw Up();
        break;
    case 2:
        throw Fit();
        break;
    }
    g();
}

// g() {}      version1
void g() { throw 47; } // version2

void my_unexcept()
{
    cout << "unexcepted exception thrown" << endl;
    exit(0);
}

int main(int argc, char const *argv[])
{
    set_unexpected(my_unexcept);
    for (int i = 1; i <= 3; i++)
    {
        try
        {
            f(i);
        }
        catch (Up)
        {
            cout << "Up cought" << endl;
        }
        catch (Fit)
        {
            cout << "Fit cought" << endl;
        }
    }
    return 0;
}
/*output:
Up cought
Fit cought
unexcepted exception thrown
*/
```

---

#### 3. 额外知识：noexcept和throw()的主要区别

##### 3.1 语义上的区别：

- noexcept：表示函数不会抛出任何异常，如果函数抛出了异常，程序会调用std::terminate()函数来终止程序。
- throw()：表示函数可能会抛出异常，但是不会抛出任何非指定类型的异常。如果函数抛出了非指定类型的异常，程序会调用std::unexpected()函数来终止程序。

##### 3.2 实现方式上的区别：

- noexcept：使用了C++11中新引入的关键字noexcept来表示函数不会抛出异常。
- throw()：使用了旧版本的异常规范（exception specification）来表示函数可能会抛出异常，但是只会抛出指定类型的异常。

> 需要注意的是，C++11标准中已经将异常规范（包括throw()）标记为废弃（deprecated），建议使用noexcept来代替。因为异常规范在实践中的效果并不理想，很难保证函数不会抛出其他类型的异常，而noexcept则更加严格和可靠。

#### 4. 在unexpected函数中再次抛出异常（unexpected函数的特有行为）

> 可以在unexpected函数中再次抛出一个异常，或是将原有异常抛出。如果再次抛出的异常不再触发unexpected函数本身的异常修饰符，则程序将会恢复到该函数被隐式调用的地方重新匹配catch块。

如果再次触发，则会发生以下两种情况之一：

* 如果函数的异常规格说明中包含`std::bad_exception`，则unexpected函数抛出的异常将会被取代为`std::bad_exception`，再恢复并重新匹配catch块。
	* （使用set_unexpected函数可以修改unexpected函数的异常规格说明）
* 不包含上述类，则会触发`terminate()`。

##### 案例

```C++
#include <exception>
#include <iostream>
using namespace std;

class A
{
};
class B
{
};

void my_handler()
{
    cout << "terminate called" << endl;
    exit(0);
}

void my_uhandler1() { throw A(); }
void my_uhandler2() { throw; }

void t() { throw B(); }

void f() throw(A) { t(); }
void g() throw(A, bad_exception) { t(); }

int main(int argc, char const *argv[])
{
    set_terminate(my_handler);
    set_unexpected(my_uhandler1);
    try
    {
        f();
    }
    catch (A &)
    {
        cout << "cought an A from f" << endl;
    }
    set_unexpected(my_uhandler2);
    try
    {
        g();
    }
    catch (bad_exception &)
    {
        cout << "cought a bad_exception form g" << endl;
    }
    try
    {
        f();
    }
    catch (...)
    {
        cout << "This is never print" << endl;
    }

    return 0;
}
/*output:
cought an A from f
cought a bad_exception form g
terminate called
*/
```

#### 5. 异常规格说明和继承

>由于异常规格说明在逻辑上也是函数声明的一部分，所以在继承层次结构中也必须保持一致。可以抛出基类成员函数的异常说明规格原有类或派生类。但不允许抛出父类。
>
>下面是一个案例说明：f函数是不允许的，但是g函数是允许的。因为DerivedException是一个BaseException，但反过来不是。

```C++
#include <iostream>
using namespace std;

class Base
{
public:
    class BaseException
    {
    };
    class DerivedException : public BaseException
    {
    };
    virtual void f() throw(DerivedException) { throw DerivedException(); }
    virtual void g() throw(BaseException) { throw BaseException(); }
};

class Derived : public Base
{
public:
    void f() throw(BaseException) { throw BaseException(); }
    void g() throw(DerivedException) { throw DerivedException(); }
};
```

